use Core.assert

error ErrArithmetic:
    ZeroDivision;

def divide(i32 x, i32 y) -> i32:
    if y == 0:
        throw ErrArithmetic.ZeroDivision;
    return x / y;

def catch_this(i32 x, i32 y) -> i32:
    return divide(x, y);

def test_error():
    i32 res = divide(10, 2);
    assert(res == 5);

    res = divide(10, 0) catch err:
        assert(err.type_id == 1484029712);
        assert(err.value_id == 0);
        assert(err.message == "");
    assert(res == 0);

    res = catch_this(10, 5) catch err:
        assert(false);
    assert(res == 2);

    res = catch_this(10, 0) catch err:
        assert(err.type_id == 1484029712);
        assert(err.value_id == 0);
        assert(err.message == "");
    assert(res == 0);

    assert(false) catch err:
        assert(err.type_id == -1846361924);
        assert(err.value_id == 0);
        assert(err.message == "The assertion has failed");
